Workbook

Sheet Registro Semanal
A1: 📊 REGISTRO SEMANAL - SC LEAD
A3: Semana: | D3: Período: | G3: Sitio:
A4: ⏱️ Tiempo: 10-15 min | Complete solo celdas AZULES | Los KPIs se calculan automáticamente
A6: 🎯 RECLUTAMIENTO | E6: 📈 KPIs CALCULADOS
A7: Métrica | B7: Valor | C7: Notas | E7: ID | F7: KPI | G7: Valor | H7: Meta | I7: Estado
A8: Pacientes screeneados (semana) | E8: SC-001 | F8: Screen Failure Rate | G8: =IF(B8>0,B10/B8*100,"-") -> - | H8: ≤15% | I8: =IF(G8="-","⚪",IF(G8<=15,"✅","❌")) -> ⚪
A9: Pacientes randomizados (semana) | E9: SC-002 | F9: Conversión Screening→Random | G9: =IF(B8>0,B9/B8*100,"-") -> - | H9: ≥35% | I9: =IF(G9="-","⚪",IF(G9>=35,"✅","❌")) -> ⚪
A10: Screen Failures (semana) | E10: SC-004 | F10: % Cumplimiento Target Mes | G10: =IF(B11>0,B12/B11*100,"-") -> - | H10: ≥85% | I10: =IF(G10="-","⚪",IF(G10>=85,"✅","❌")) -> ⚪
A11: Target reclutamiento mensual | E11: SC-005 | F11: Randomizados vs Proyección | G11: =IF(B13>0,B14/B13*100,"-") -> - | H11: ≥90% | I11: =IF(G11="-","⚪",IF(G11>=90,"✅","❌")) -> ⚪
A12: Randomizados acumulado mes
A13: Proyección randomizados semana
A14: Randomizados reales semana
A17: 📋 EJECUCIÓN DE VISITAS | E17: 📈 KPIs CALCULADOS
A18: Métrica | B18: Valor | C18: Notas | E18: ID | F18: KPI | G18: Valor | H18: Meta | I18: Estado
A19: Visitas planificadas (semana) | E19: SC-006 | F19: % Visitas Completadas | G19: =IF(B19>0,B20/B19*100,"-") -> - | H19: ≥90% | I19: =IF(G19="-","⚪",IF(G19>=90,"✅","❌")) -> ⚪
A20: Visitas completadas | E20: SC-007 | F20: % Adherencia Ventana Visita | G20: =IF(B20>0,B21/B20*100,"-") -> - | H20: ≥90% | I20: =IF(G20="-","⚪",IF(G20>=90,"✅","❌")) -> ⚪
A21: Visitas dentro de ventana protocolo | E21: SC-008 | F21: % Procedimientos Completos | G21: =IF(B20>0,B22/B20*100,"-") -> - | H21: ≥95% | I21: =IF(G21="-","⚪",IF(G21>=95,"✅","❌")) -> ⚪
A22: Visitas con procedimientos completos | E22: SC-009 | F22: Retención Pacientes (mes) | G22: =IF(B23>0,(B23-B24)/B23*100,"-") -> - | H22: ≥90% | I22: =IF(G22="-","⚪",IF(G22>=90,"✅","❌")) -> ⚪
A23: Pacientes activos (ongoing) inicio mes
A24: Pacientes retirados/perdidos mes
A27: ⚠️ SEGURIDAD Y COMPLIANCE | E27: 📈 KPIs CALCULADOS
A28: Métrica | B28: Valor | C28: Notas | E28: ID | F28: KPI | G28: Valor | H28: Meta | I28: Estado
A29: SAEs identificados (semana) | E29: SC-010 | F29: % SAEs Reportados en Plazo | G29: =IF(B29>0,B30/B29*100,"-") -> - | H29: =100% -> 1 | I29: =IF(G29="-","⚪",IF(G29=100,"✅","❌")) -> ⚪
A30: SAEs reportados en <24h | E30: SC-011 | F30: Desviaciones Mayores (sem) | G30: =B31 -> 0 | H30: ≤2 | I30: =IF(G30="-","⚪",IF(G30<=2,"✅","❌")) -> ✅
A31: Desviaciones mayores (semana) | E31: SC-012 | F31: Tasa Desviaciones Protocolo | G31: =IF(B33>0,B32/B33*100,"-") -> - | H31: ≤3% | I31: =IF(G31="-","⚪",IF(G31<=3,"✅","❌")) -> ⚪
A32: Total desviaciones mes | E32: SC-013 | F32: Tasa Desviaciones Mayores | G32: =IF(B33>0,B34/B33*100,"-") -> - | H32: ≤1% | I32: =IF(G32="-","⚪",IF(G32<=1,"✅","❌")) -> ⚪
A33: Total visitas/procedimientos mes | E33: SC-014 | F33: CAPAs Abiertas | G33: =B35 -> 0 | H33: ≤3 | I33: =IF(G33="-","⚪",IF(G33<=3,"✅","❌")) -> ✅
A34: Desviaciones mayores mes
A35: CAPAs abiertas del área
A38: ⚙️ EFICIENCIA OPERATIVA | E38: 📈 KPIs CALCULADOS
A39: Métrica | B39: Valor | C39: Notas | E39: ID | F39: KPI | G39: Valor | H39: Meta | I39: Estado
A40: Total coordinadores activos | E40: SC-040 | F40: Estudios por Coordinador | G40: =IF(B40>0,B41/B40,"-") -> - | H40: 3-5 | I40: =IF(G40="-","⚪",IF(AND(G40>=3,G40<=5),"✅","⚠️")) -> ⚪
A41: Total estudios activos | E41: SC-041 | F41: Pacientes por Coordinador | G41: =IF(B40>0,B42/B40,"-") -> - | H41: 15-25 | I41: =IF(G41="-","⚪",IF(AND(G41>=15,G41<=25),"✅","⚠️")) -> ⚪
A42: Total pacientes activos (ongoing) | E42: SC-043 | F42: % Participación MV/SIV | G42: =IF(B43>0,B44/B43*100,"-") -> - | H42: =100% -> 1 | I42: =IF(G42="-","⚪",IF(G42=100,"✅","❌")) -> ⚪
A43: MV/SIV programadas semana
A44: MV/SIV con participación SC Lead

Sheet Tracking Action Items
A1: 📝 TRACKING ACTION ITEMS - MONITORING VISITS
A2: Registre cada Action Item. Las métricas se calculan automáticamente abajo.
A4: ID | B4: Estudio | C4: Fecha MV | D4: Descripción | E4: Categoría | F4: Severidad | G4: Responsable | H4: Fecha Límite | I4: Fecha Cierre | J4: Estado | K4: Días Abierto | L4: ¿En Plazo?
A5: AI-001 | K5: =IF(J5="Cerrado",I5-C5,IF(C5="","",TODAY()-C5)) | L5: =IF(J5="","",IF(J5="Cerrado",IF(I5<=H5,"Sí","No"),IF(TODAY()<=H5,"En tiempo","Vencido")))
A6: AI-002 | K6: =IF(J6="Cerrado",I6-C6,IF(C6="","",TODAY()-C6)) | L6: =IF(J6="","",IF(J6="Cerrado",IF(I6<=H6,"Sí","No"),IF(TODAY()<=H6,"En tiempo","Vencido")))
A7: AI-003 | K7: =IF(J7="Cerrado",I7-C7,IF(C7="","",TODAY()-C7)) | L7: =IF(J7="","",IF(J7="Cerrado",IF(I7<=H7,"Sí","No"),IF(TODAY()<=H7,"En tiempo","Vencido")))
A8: AI-004 | K8: =IF(J8="Cerrado",I8-C8,IF(C8="","",TODAY()-C8)) | L8: =IF(J8="","",IF(J8="Cerrado",IF(I8<=H8,"Sí","No"),IF(TODAY()<=H8,"En tiempo","Vencido")))
A9: AI-005 | K9: =IF(J9="Cerrado",I9-C9,IF(C9="","",TODAY()-C9)) | L9: =IF(J9="","",IF(J9="Cerrado",IF(I9<=H9,"Sí","No"),IF(TODAY()<=H9,"En tiempo","Vencido")))
A10: AI-006 | K10: =IF(J10="Cerrado",I10-C10,IF(C10="","",TODAY()-C10)) | L10: =IF(J10="","",IF(J10="Cerrado",IF(I10<=H10,"Sí","No"),IF(TODAY()<=H10,"En tiempo","Vencido")))
A11: AI-007 | K11: =IF(J11="Cerrado",I11-C11,IF(C11="","",TODAY()-C11)) | L11: =IF(J11="","",IF(J11="Cerrado",IF(I11<=H11,"Sí","No"),IF(TODAY()<=H11,"En tiempo","Vencido")))
A12: AI-008 | K12: =IF(J12="Cerrado",I12-C12,IF(C12="","",TODAY()-C12)) | L12: =IF(J12="","",IF(J12="Cerrado",IF(I12<=H12,"Sí","No"),IF(TODAY()<=H12,"En tiempo","Vencido")))
A13: AI-009 | K13: =IF(J13="Cerrado",I13-C13,IF(C13="","",TODAY()-C13)) | L13: =IF(J13="","",IF(J13="Cerrado",IF(I13<=H13,"Sí","No"),IF(TODAY()<=H13,"En tiempo","Vencido")))
A14: AI-010 | K14: =IF(J14="Cerrado",I14-C14,IF(C14="","",TODAY()-C14)) | L14: =IF(J14="","",IF(J14="Cerrado",IF(I14<=H14,"Sí","No"),IF(TODAY()<=H14,"En tiempo","Vencido")))
A15: AI-011 | K15: =IF(J15="Cerrado",I15-C15,IF(C15="","",TODAY()-C15)) | L15: =IF(J15="","",IF(J15="Cerrado",IF(I15<=H15,"Sí","No"),IF(TODAY()<=H15,"En tiempo","Vencido")))
A16: AI-012 | K16: =IF(J16="Cerrado",I16-C16,IF(C16="","",TODAY()-C16)) | L16: =IF(J16="","",IF(J16="Cerrado",IF(I16<=H16,"Sí","No"),IF(TODAY()<=H16,"En tiempo","Vencido")))
... A44: AI-040 | K44: =IF(J44="Cerrado",I44-C44,IF(C44="","",TODAY()-C44)) | L44: =IF(J44="","",IF(J44="Cerrado",IF(I44<=H44,"Sí","No"),IF(TODAY()<=H44,"En tiempo","Vencido")))
A47: 📊 MÉTRICAS AUTOMÁTICAS - ACTION ITEMS
A48: ID | B48: Métrica | C48: Valor | D48: Meta | E48: Estado
A49: SC-019 | B49: Action Items Abiertos | C49: =COUNTIF(J5:J44,"Abierto")+COUNTIF(J5:J44,"En Progreso") -> 0 | D49: ≤5 | E49: =IF(C49<=5,"✅","❌") -> ✅
A50: SC-020 | B50: % AI Cerrados en Plazo (≤15d) | C50: =IF(COUNTIF(J5:J44,"Cerrado")>0,COUNTIFS(J5:J44,"Cerrado",K5:K44,"<=15")/COUNTIF(J5:J44,"Cerrado")*100,"-") -> - | D50: ≥90% | E50: =IF(C50="-","⚪",IF(C50>=90,"✅","❌")) -> ⚪
A51: SC-021 | B51: AI Vencidos (>15 días abiertos) | C51: =COUNTIFS(J5:J44,"<>Cerrado",K5:K44,">15") -> 0 | D51: =0 -> 0 | E51: =IF(C51=0,"✅","❌") -> ✅
A52: SC-022 | B52: Promedio Días Cierre | C52: =IF(COUNTIF(J5:J44,"Cerrado")>0,AVERAGEIF(J5:J44,"Cerrado",K5:K44),"-") -> - | D52: ≤10 | E52: =IF(C52="-","⚪",IF(C52<=10,"✅","❌")) -> ⚪
A53: SC-023 | B53: % Major Findings | C53: =IF(COUNTA(F5:F44)>0,COUNTIF(F5:F44,"Major")/COUNTA(F5:F44)*100,"-") -> - | D53: ≤5% | E53: =IF(C53="-","⚪",IF(C53<=5,"✅","❌")) -> ⚪

Sheet Contacto Pacientes
A1: 📞 REGISTRO CONTACTO PACIENTES - TIEMPO DE RESPUESTA
A2: Registre cada paciente derivado para medir tiempo de contacto (KPI SC-003)
A4: ID | B4: Estudio | C4: Fecha Derivación | D4: Fecha Contacto | E4: Días hasta Contacto | F4: ¿En Meta? | G4: Fuente Derivación | H4: Comentario
A5: P-001 | E5: =IF(OR(C5="",D5=""),"",D5-C5) | F5: =IF(E5="","",IF(E5<=1,"✅","❌"))
A6: P-002 | E6: =IF(OR(C6="",D6=""),"",D6-C6) | F6: =IF(E6="","",IF(E6<=1,"✅","❌"))
A7: P-003 | E7: =IF(OR(C7="",D7=""),"",D7-C7) | F7: =IF(E7="","",IF(E7<=1,"✅","❌"))
A8: P-004 | E8: =IF(OR(C8="",D8=""),"",D8-C8) | F8: =IF(E8="","",IF(E8<=1,"✅","❌"))
A9: P-005 | E9: =IF(OR(C9="",D9=""),"",D9-C9) | F9: =IF(E9="","",IF(E9<=1,"✅","❌"))
A10: P-006 | E10: =IF(OR(C10="",D10=""),"",D10-C10) | F10: =IF(E10="","",IF(E10<=1,"✅","❌"))
A11: P-007 | E11: =IF(OR(C11="",D11=""),"",D11-C11) | F11: =IF(E11="","",IF(E11<=1,"✅","❌"))
A12: P-008 | E12: =IF(OR(C12="",D12=""),"",D12-C12) | F12: =IF(E12="","",IF(E12<=1,"✅","❌"))
A13: P-009 | E13: =IF(OR(C13="",D13=""),"",D13-C13) | F13: =IF(E13="","",IF(E13<=1,"✅","❌"))
A14: P-010 | E14: =IF(OR(C14="",D14=""),"",D14-C14) | F14: =IF(E14="","",IF(E14<=1,"✅","❌"))
A15: P-011 | E15: =IF(OR(C15="",D15=""),"",D15-C15) | F15: =IF(E15="","",IF(E15<=1,"✅","❌"))
A16: P-012 | E16: =IF(OR(C16="",D16=""),"",D16-C16) | F16: =IF(E16="","",IF(E16<=1,"✅","❌"))
... A54: P-050 | E54: =IF(OR(C54="",D54=""),"",D54-C54) | F54: =IF(E54="","",IF(E54<=1,"✅","❌"))
A57: 📊 MÉTRICAS
A58: SC-003 | B58: Tiempo Promedio Derivación→Contacto | C58: =IF(COUNT(E5:E54)>0,AVERAGE(E5:E54),"-") -> - | D58: ≤1 día | E58: =IF(C58="-","⚪",IF(C58<=1,"✅","❌")) -> ⚪
B59: % Contactados en ≤1 día | C59: =IF(COUNT(E5:E54)>0,COUNTIF(E5:E54,"<=1")/COUNT(E5:E54)*100,"-") -> - | D59: ≥90% | E59: =IF(C59="-","⚪",IF(C59>=90,"✅","❌")) -> ⚪

Sheet Start-up Tracker
A1: 🚀 START-UP TRACKER - ESTUDIOS EN ACTIVACIÓN
A3: ID | B3: Estudio | C3: Sponsor | D3: Fecha Sometimiento EC | E3: Fecha Aprobación EC | F3: Días Ciclo EC | G3: Fecha Última Aprobación | H3: Fecha FPFV | I3: Días hasta FPFV | J3: ¿FPFV ≤30d? | K3: Re-sometimiento? | L3: Estado
A4: ST-001 | F4: =IF(OR(D4="",E4=""),"",E4-D4) | I4: =IF(OR(G4="",H4=""),"",H4-G4) | J4: =IF(I4="","",IF(I4<=30,"✅","❌"))
A5: ST-002 | F5: =IF(OR(D5="",E5=""),"",E5-D5) | I5: =IF(OR(G5="",H5=""),"",H5-G5) | J5: =IF(I5="","",IF(I5<=30,"✅","❌"))
A6: ST-003 | F6: =IF(OR(D6="",E6=""),"",E6-D6) | I6: =IF(OR(G6="",H6=""),"",H6-G6) | J6: =IF(I6="","",IF(I6<=30,"✅","❌"))
A7: ST-004 | F7: =IF(OR(D7="",E7=""),"",E7-D7) | I7: =IF(OR(G7="",H7=""),"",H7-G7) | J7: =IF(I7="","",IF(I7<=30,"✅","❌"))
A8: ST-005 | F8: =IF(OR(D8="",E8=""),"",E8-D8) | I8: =IF(OR(G8="",H8=""),"",H8-G8) | J8: =IF(I8="","",IF(I8<=30,"✅","❌"))
A9: ST-006 | F9: =IF(OR(D9="",E9=""),"",E9-D9) | I9: =IF(OR(G9="",H9=""),"",H9-G9) | J9: =IF(I9="","",IF(I9<=30,"✅","❌"))
A10: ST-007 | F10: =IF(OR(D10="",E10=""),"",E10-D10) | I10: =IF(OR(G10="",H10=""),"",H10-G10) | J10: =IF(I10="","",IF(I10<=30,"✅","❌"))
A11: ST-008 | F11: =IF(OR(D11="",E11=""),"",E11-D11) | I11: =IF(OR(G11="",H11=""),"",H11-G11) | J11: =IF(I11="","",IF(I11<=30,"✅","❌"))
A12: ST-009 | F12: =IF(OR(D12="",E12=""),"",E12-D12) | I12: =IF(OR(G12="",H12=""),"",H12-G12) | J12: =IF(I12="","",IF(I12<=30,"✅","❌"))
A13: ST-010 | F13: =IF(OR(D13="",E13=""),"",E13-D13) | I13: =IF(OR(G13="",H13=""),"",H13-G13) | J13: =IF(I13="","",IF(I13<=30,"✅","❌"))
A14: ST-011 | F14: =IF(OR(D14="",E14=""),"",E14-D14) | I14: =IF(OR(G14="",H14=""),"",H14-G14) | J14: =IF(I14="","",IF(I14<=30,"✅","❌"))
A15: ST-012 | F15: =IF(OR(D15="",E15=""),"",E15-D15) | I15: =IF(OR(G15="",H15=""),"",H15-G15) | J15: =IF(I15="","",IF(I15<=30,"✅","❌"))
... A23: ST-020 | F23: =IF(OR(D23="",E23=""),"",E23-D23) | I23: =IF(OR(G23="",H23=""),"",H23-G23) | J23: =IF(I23="","",IF(I23<=30,"✅","❌"))
A26: 📊 MÉTRICAS START-UP
A27: SC-025 | B27: Tiempo Promedio hasta FPFV | C27: =IF(COUNT(I4:I23)>0,AVERAGE(I4:I23),"-") -> - | D27: ≤30 días | E27: =IF(C27="-","⚪",IF(C27<=30,"✅","❌")) -> ⚪
A28: SC-026 | B28: % Estudios con FPFV ≤30 días | C28: =IF(COUNT(I4:I23)>0,COUNTIF(I4:I23,"<=30")/COUNT(I4:I23)*100,"-") -> - | D28: ≥85% | E28: =IF(C28="-","⚪",IF(C28>=85,"✅","❌")) -> ⚪
A29: SC-027 | B29: % Sometimientos sin Re-sometimiento | C29: =IF(COUNTA(K4:K23)>0,COUNTIF(K4:K23,"No")/COUNTA(K4:K23)*100,"-") -> - | D29: ≥90% | E29: =IF(C29="-","⚪",IF(C29>=90,"✅","❌")) -> ⚪
A30: SC-028 | B30: Tiempo Promedio Ciclo EC | C30: =IF(COUNT(F4:F23)>0,AVERAGE(F4:F23),"-") -> - | D30: ≤45 días | E30: =IF(C30="-","⚪",IF(C30<=45,"✅","❌")) -> ⚪
A31: SC-029 | B31: Estudios en Start-Up Activos | C31: =COUNTIF(L4:L23,"<>FPFV Logrado")-COUNTIF(L4:L23,"Suspendido") -> 20 | D31: Info | E31: ℹ️
A32: SC-030 | B32: Enmiendas Pendientes | C32: =COUNTIF(L4:L23,"Aprobación Pendiente") -> 0 | D32: Info | E32: ℹ️

Sheet Consultas CRA-Sponsor
A1: 📧 REGISTRO CONSULTAS CRA/SPONSOR
A3: ID | B3: Fecha Recepción | C3: Estudio | D3: Origen | E3: Descripción | F3: Fecha Respuesta | G3: Horas hasta Respuesta | H3: ¿En Meta?
A4: Q-001 | G4: =IF(OR(B4="",F4=""),"",(F4-B4)*24) | H4: =IF(G4="","",IF(G4<=48,"✅","❌"))
A5: Q-002 | G5: =IF(OR(B5="",F5=""),"",(F5-B5)*24) | H5: =IF(G5="","",IF(G5<=48,"✅","❌"))
A6: Q-003 | G6: =IF(OR(B6="",F6=""),"",(F6-B6)*24) | H6: =IF(G6="","",IF(G6<=48,"✅","❌"))
A7: Q-004 | G7: =IF(OR(B7="",F7=""),"",(F7-B7)*24) | H7: =IF(G7="","",IF(G7<=48,"✅","❌"))
A8: Q-005 | G8: =IF(OR(B8="",F8=""),"",(F8-B8)*24) | H8: =IF(G8="","",IF(G8<=48,"✅","❌"))
A9: Q-006 | G9: =IF(OR(B9="",F9=""),"",(F9-B9)*24) | H9: =IF(G9="","",IF(G9<=48,"✅","❌"))
A10: Q-007 | G10: =IF(OR(B10="",F10=""),"",(F10-B10)*24) | H10: =IF(G10="","",IF(G10<=48,"✅","❌"))
A11: Q-008 | G11: =IF(OR(B11="",F11=""),"",(F11-B11)*24) | H11: =IF(G11="","",IF(G11<=48,"✅","❌"))
A12: Q-009 | G12: =IF(OR(B12="",F12=""),"",(F12-B12)*24) | H12: =IF(G12="","",IF(G12<=48,"✅","❌"))
A13: Q-010 | G13: =IF(OR(B13="",F13=""),"",(F13-B13)*24) | H13: =IF(G13="","",IF(G13<=48,"✅","❌"))
A14: Q-011 | G14: =IF(OR(B14="",F14=""),"",(F14-B14)*24) | H14: =IF(G14="","",IF(G14<=48,"✅","❌"))
A15: Q-012 | G15: =IF(OR(B15="",F15=""),"",(F15-B15)*24) | H15: =IF(G15="","",IF(G15<=48,"✅","❌"))
... A53: Q-050 | G53: =IF(OR(B53="",F53=""),"",(F53-B53)*24) | H53: =IF(G53="","",IF(G53<=48,"✅","❌"))
A56: 📊 MÉTRICAS CONSULTAS
A57: SC-032 | B57: % Consultas Respondidas ≤48h | C57: =IF(COUNT(G4:G53)>0,COUNTIF(G4:G53,"<=48")/COUNT(G4:G53)*100,"-") -> - | D57: ≥90% | E57: =IF(C57="-","⚪",IF(C57>=90,"✅","❌")) -> ⚪

Sheet Gestión Equipo
A1: 👥 GESTIÓN DE EQUIPO - SC LEAD
A3: 📋 ROSTER DEL EQUIPO
A4: # | B4: Nombre | C4: Cargo | D4: Fecha Ingreso | E4: GCP Vigente? | F4: Venc. GCP | G4: Eval. Desempeño | H4: Workload Score | I4: Estudios Asig. | J4: Pacientes Asig.
A5: 1
A6: 2
A7: 3
A8: 4
A9: 5
A10: 6
A11: 7
A12: 8
A13: 9
A14: 10
A15: 11
A16: 12
... A19: 15
A22: 📊 MOVIMIENTOS DE PERSONAL (Año actual) | D22: ID | E22: KPI | F22: Valor | G22: Meta | H22: Estado
A23: Métrica | B23: Valor | D23: SC-034 | E23: Turnover Anual | F23: =IF(B24>0,B26/B24*100,"-") -> - | G23: ≤18% | H23: =IF(G23="-","⚪",IF(G23<=18,"✅","❌")) -> ❌
A24: Headcount inicio año | D24: SC-035 | E24: % Eval. Satisfactoria | F24: =IF(COUNTA(G5:G19)>0,(COUNTIF(G5:G19,"Excepcional")+COUNTIF(G5:G19,"Satisfactorio"))/COUNTA(G5:G19)*100,"-") -> - | G24: ≥80% | H24: =IF(G24="-","⚪",IF(G24>=80,"✅","❌")) -> ✅
A25: Ingresos año | D25: SC-036 | E25: % GCP Vigente | F25: =IF(COUNTA(E5:E19)>0,COUNTIF(E5:E19,"Sí")/COUNTA(E5:E19)*100,"-") -> - | G25: =100% -> 1 | H25: =IF(G25="-","⚪",IF(G25=100,"✅","❌")) -> ❌
A26: Salidas año | D26: SC-037 | E26: Span of Control | F26: =COUNTA(B5:B19) -> 0 | G26: ≤8 | H26: =IF(G26<=8,"✅","⚠️") -> ⚠️
A27: Headcount actual | D27: SC-038 | E27: % Training Completado | F27: =IF(B32>0,B33/B32*100,"-") -> - | G27: ≥90% | H27: =IF(G27="-","⚪",IF(G27>=90,"✅","❌")) -> ✅
D28: SC-039 | E28: Workload Score Prom. | F28: =IF(COUNT(H5:H19)>0,AVERAGE(H5:H19),"-") -> - | G28: 2.5-3.5 | H28: =IF(G28="-","⚪",IF(AND(G28>=2.5,G28<=3.5),"✅","⚠️")) -> ⚠️
A30: 📚 TRAINING
A31: Métrica | B31: Valor
A32: Trainings planificados mes
A33: Trainings completados mes

Sheet Evaluación Sponsor
A1: ⭐ EVALUACIÓN DE SPONSORS - TRIMESTRAL
A3: Trimestre | B3: Sponsor | C3: Estudio | D3: Score Performance (1-5) | E3: NPS (0-10) | F3: Comentarios | G3: Fecha Evaluación
A26: 📊 MÉTRICAS SATISFACCIÓN
A27: SC-031 | B27: Score Promedio Performance | C27: =IF(COUNT(D4:D23)>0,AVERAGE(D4:D23),"-") -> - | D27: ≥4.0/5.0 | E27: =IF(C27="-","⚪",IF(C27>=4,"✅","❌")) -> ⚪
A28: SC-033 | B28: NPS Promedio Sponsors | C28: =IF(COUNT(E4:E23)>0,AVERAGE(E4:E23),"-") -> - | D28: ≥8.0/10 | E28: =IF(C28="-","⚪",IF(C28>=8,"✅","❌")) -> ⚪

Sheet Contingencias
A1: 🔥 REGISTRO DE CONTINGENCIAS
A3: ID | B3: Fecha Reporte | C3: Estudio | D3: Descripción | E3: Prioridad | F3: Fecha Resolución | G3: Horas Resolución | H3: ¿En Meta?
A4: C-001 | G4: =IF(OR(B4="",F4=""),"",(F4-B4)*24) | H4: =IF(G4="","",IF(G4<=4,"✅","❌"))
A5: C-002 | G5: =IF(OR(B5="",F5=""),"",(F5-B5)*24) | H5: =IF(G5="","",IF(G5<=4,"✅","❌"))
A6: C-003 | G6: =IF(OR(B6="",F6=""),"",(F6-B6)*24) | H6: =IF(G6="","",IF(G6<=4,"✅","❌"))
A7: C-004 | G7: =IF(OR(B7="",F7=""),"",(F7-B7)*24) | H7: =IF(G7="","",IF(G7<=4,"✅","❌"))
A8: C-005 | G8: =IF(OR(B8="",F8=""),"",(F8-B8)*24) | H8: =IF(G8="","",IF(G8<=4,"✅","❌"))
A9: C-006 | G9: =IF(OR(B9="",F9=""),"",(F9-B9)*24) | H9: =IF(G9="","",IF(G9<=4,"✅","❌"))
A10: C-007 | G10: =IF(OR(B10="",F10=""),"",(F10-B10)*24) | H10: =IF(G10="","",IF(G10<=4,"✅","❌"))
A11: C-008 | G11: =IF(OR(B11="",F11=""),"",(F11-B11)*24) | H11: =IF(G11="","",IF(G11<=4,"✅","❌"))
A12: C-009 | G12: =IF(OR(B12="",F12=""),"",(F12-B12)*24) | H12: =IF(G12="","",IF(G12<=4,"✅","❌"))
A13: C-010 | G13: =IF(OR(B13="",F13=""),"",(F13-B13)*24) | H13: =IF(G13="","",IF(G13<=4,"✅","❌"))
A14: C-011 | G14: =IF(OR(B14="",F14=""),"",(F14-B14)*24) | H14: =IF(G14="","",IF(G14<=4,"✅","❌"))
A15: C-012 | G15: =IF(OR(B15="",F15=""),"",(F15-B15)*24) | H15: =IF(G15="","",IF(G15<=4,"✅","❌"))
... A33: C-030 | G33: =IF(OR(B33="",F33=""),"",(F33-B33)*24) | H33: =IF(G33="","",IF(G33<=4,"✅","❌"))
A36: 📊 MÉTRICA
A37: SC-042 | B37: Tiempo Promedio Resolución | C37: =IF(COUNT(G4:G33)>0,AVERAGE(G4:G33),"-") -> - | D37: ≤4 horas | E37: =IF(C37="-","⚪",IF(C37<=4,"✅","❌")) -> ⚪

Sheet Audit Readiness
A1: 🔍 AUDIT READINESS CHECKLIST - MENSUAL
A3: Mes/Año:
A5: # | B5: Área de Evaluación | C5: Criterio | D5: Cumple? | E5: Evidencia/Comentario | F5: Peso
A6: 1 | B6: ISF completos y actualizados | C6: Todos los ISF tienen documentos esenciales actualizados | F6: 15
A7: 2 | B7: Regulatory files vigentes | C7: Aprobaciones EC y regulatorias al día | F7: 15
A8: 3 | B8: Logs de delegación actualizados | C8: Delegation logs y training logs completos | F8: 10
A9: 4 | B9: Consentimientos verificados | C9: ICFs firmados, fechados y versión correcta | F9: 15
A10: 5 | B10: Source documents completos | C10: Documentos fuente para todas las visitas | F10: 15
A11: 6 | B11: SAEs documentados | C11: Todos los SAEs con documentación completa | F11: 10
A12: 7 | B12: Desviaciones documentadas | C12: Todas las desviaciones reportadas y con CAPA | F12: 10
A13: 8 | B13: eTMF actualizado | C13: Documentos subidos según timeline requerido | F13: 10
A16: 📊 SCORE
A17: SC-024 | B17: Audit Readiness Score | C17: =IF(COUNTA(D6:D13)>0,(SUMPRODUCT((D6:D13="Sí")*F6:F13)+SUMPRODUCT((D6:D13="Parcial")*F6:F13*0.5))/SUM(F6:F13)*100,"-") -> - | D17: ≥90% | E17: =IF(C17="-","⚪",IF(C17>=90,"✅","❌")) -> ⚪

Sheet Scorecard SC Lead
A1: 📊 SCORECARD CONSOLIDADO - SC LEAD
A3: Período: | D3: Sitio:
A4: Este scorecard consolida automáticamente los KPIs de todas las hojas de registro
A6: # | B6: ID | C6: KPI | D6: Valor | E6: Meta | F6: Estado
A7: 🎯 RECLUTAMIENTO
A8: 1 | B8: SC-001 | C8: Screen Failure Rate | D8: ='Registro Semanal'!G8 -> - | E8: ≤15% | F8: ='Registro Semanal'!I8 -> ⚪
A9: 2 | B9: SC-002 | C9: Conversión Screening→Randomizado | D9: ='Registro Semanal'!G9 -> - | E9: ≥35% | F9: ='Registro Semanal'!I9 -> ⚪
A10: 3 | B10: SC-003 | C10: Tiempo Derivación→Contacto | D10: ='Contacto Pacientes'!C58 -> - | E10: ≤1 día | F10: ='Contacto Pacientes'!E58 -> ⚪
A11: 4 | B11: SC-004 | C11: % Cumplimiento Targets Reclutamiento | D11: ='Registro Semanal'!G10 -> - | E11: ≥85% | F11: ='Registro Semanal'!I10 -> ⚪
A12: 5 | B12: SC-005 | C12: Randomizados vs Proyección | D12: ='Registro Semanal'!G11 -> - | E12: ≥90% | F12: ='Registro Semanal'!I11 -> ⚪
A13: 📋 EJECUCIÓN DE VISITAS
A14: 6 | B14: SC-006 | C14: % Visitas Completadas | D14: ='Registro Semanal'!G19 -> - | E14: ≥90% | F14: ='Registro Semanal'!I19 -> ⚪
A15: 7 | B15: SC-007 | C15: % Adherencia Ventana Visita | D15: ='Registro Semanal'!G20 -> - | E15: ≥90% | F15: ='Registro Semanal'!I20 -> ⚪
A16: 8 | B16: SC-008 | C16: % Procedimientos Completos | D16: ='Registro Semanal'!G21 -> - | E16: ≥95% | F16: ='Registro Semanal'!I21 -> ⚪
A17: 9 | B17: SC-009 | C17: Retención de Pacientes (mes) | D17: ='Registro Semanal'!G22 -> - | E17: ≥90% | F17: ='Registro Semanal'!I22 -> ⚪
A18: ⚠️ SEGURIDAD Y COMPLIANCE
A19: 10 | B19: SC-010 | C19: % SAEs Reportados en Plazo | D19: ='Registro Semanal'!G29 -> - | E19: =100% -> 1 | F19: ='Registro Semanal'!I29 -> ⚪
A20: 11 | B20: SC-011 | C20: Desviaciones Mayores (semana) | D20: ='Registro Semanal'!G30 -> 0 | E20: ≤2 | F20: ='Registro Semanal'!I30 -> ✅
A21: 12 | B21: SC-012 | C21: Tasa Desviaciones Protocolo | D21: ='Registro Semanal'!G31 -> - | E21: ≤3% | F21: ='Registro Semanal'!I31 -> ⚪
A22: 13 | B22: SC-013 | C22: Tasa Desviaciones Mayores | D22: ='Registro Semanal'!G32 -> - | E22: ≤1% | F22: ='Registro Semanal'!I32 -> ⚪
A23: 14 | B23: SC-014 | C23: CAPAs Abiertas | D23: ='Registro Semanal'!G33 -> 0 | E23: ≤3 | F23: ='Registro Semanal'!I33 -> ✅
A24: 📝 MONITORING ACTION ITEMS
A25: 15 | B25: SC-019 | C25: Action Items Abiertos | D25: ='Tracking Action Items'!C49 -> 0 | E25: ≤5 | F25: ='Tracking Action Items'!E49 -> ✅
A26: 16 | B26: SC-020 | C26: % AI Cerrados en Plazo (≤15d) | D26: ='Tracking Action Items'!C50 -> - | E26: ≥90% | F26: ='Tracking Action Items'!E50 -> ⚪
A27: 17 | B27: SC-021 | C27: AI Vencidos (>15 días) | D27: ='Tracking Action Items'!C51 -> 0 | E27: =0 -> 0 | F27: ='Tracking Action Items'!E51 -> ✅
A28: 18 | B28: SC-022 | C28: Promedio Días Cierre AI | D28: ='Tracking Action Items'!C52 -> - | E28: ≤10 | F28: ='Tracking Action Items'!E52 -> ⚪
A29: 19 | B29: SC-023 | C29: % Major Findings en MV | D29: ='Tracking Action Items'!C53 -> - | E29: ≤5% | F29: ='Tracking Action Items'!E53 -> ⚪
A30: 20 | B30: SC-024 | C30: Audit Readiness Score | D30: ='Audit Readiness'!C17 -> - | E30: ≥90% | F30: ='Audit Readiness'!E17 -> ⚪
A31: 🚀 START-UP Y REGULATORIO
A32: 21 | B32: SC-025 | C32: Tiempo hasta FPFV (días) | D32: ='Start-up Tracker'!C27 -> - | E32: ≤30 | F32: ='Start-up Tracker'!E27 -> ⚪
A33: 22 | B33: SC-026 | C33: % Estudios con FPFV ≤30 días | D33: ='Start-up Tracker'!C28 -> - | E33: ≥85% | F33: ='Start-up Tracker'!E28 -> ⚪
A34: 23 | B34: SC-027 | C34: % Sometimientos sin Re-sometimiento | D34: ='Start-up Tracker'!C29 -> - | E34: ≥90% | F34: ='Start-up Tracker'!E29 -> ⚪
A35: 24 | B35: SC-028 | C35: Tiempo Ciclo Aprobación EC | D35: ='Start-up Tracker'!C30 -> - | E35: ≤45 días | F35: ='Start-up Tracker'!E30 -> ⚪
A36: 25 | B36: SC-029 | C36: Estudios en Start-Up Activos | D36: ='Start-up Tracker'!C31 -> 20 | E36: Info | F36: ='Start-up Tracker'!E31 -> ℹ️
A37: 26 | B37: SC-030 | C37: Enmiendas Pendientes | D37: ='Start-up Tracker'!C32 -> 0 | E37: Info | F37: ='Start-up Tracker'!E32 -> ℹ️
A38: ⭐ SATISFACCIÓN PATROCINADORES
A39: 27 | B39: SC-031 | C39: Score Evaluación Performance | D39: ='Evaluación Sponsor'!C27 -> - | E39: ≥4.0/5.0 | F39: ='Evaluación Sponsor'!E27 -> ⚪
A40: 28 | B40: SC-032 | C40: % Consultas CRA/Sponsor ≤48h | D40: ='Consultas CRA-Sponsor'!C57 -> - | E40: ≥90% | F40: ='Consultas CRA-Sponsor'!E57 -> ⚪
A41: 29 | B41: SC-033 | C41: NPS de Sponsors | D41: ='Evaluación Sponsor'!C28 -> - | E41: ≥8.0/10 | F41: ='Evaluación Sponsor'!E28 -> ⚪
A42: 👥 GESTIÓN DE EQUIPO
...

Sheet Specs VS Code
A1: 🔧 ESPECIFICACIONES TÉCNICAS - MÓDULO SC LEAD
A2: Estructura de datos para implementación en React/TypeScript + Supabase (sin KPIs de Data Quality)
A4: ID | B4: KPI Key | C4: Label | D4: Tipo Dato | E4: Meta | F4: Operador | G4: Unidad | H4: Frecuencia | I4: Categoría
A5: SC-001 | B5: screen_failure_rate | C5: Screen Failure Rate | D5: percentage | E5: 15 | F5: <= | G5: % | H5: Semanal | I5: recruitment
A6: SC-002 | B6: conversion_screening_randomized | C6: Conversión Screening→Randomizado | D6: percentage | E6: 35 | F6: >= | G6: % | H6: Semanal | I6: recruitment
A7: SC-003 | B7: days_referral_to_contact | C7: Tiempo Derivación→Contacto | D7: number | E7: 1 | F7: <= | G7: días | H7: Por paciente | I7: recruitment
A8: SC-004 | B8: recruitment_target_compliance | C8: % Cumplimiento Targets Reclutamiento | D8: percentage | E8: 85 | F8: >= | G8: % | H8: Mensual | I8: recruitment
A9: SC-005 | B9: randomized_vs_projection | C9: Randomizados vs Proyección | D9: percentage | E9: 90 | F9: >= | G9: % | H9: Semanal | I9: recruitment
A10: SC-006 | B10: visits_completed_pct | C10: % Visitas Completadas | D10: percentage | E10: 90 | F10: >= | G10: % | H10: Semanal | I10: execution
A11: SC-007 | B11: visit_window_adherence | C11: % Adherencia Ventana Visita | D11: percentage | E11: 90 | F11: >= | G11: % | H11: Semanal | I11: execution
A12: SC-008 | B12: procedures_complete_pct | C12: % Procedimientos Completos por Visita | D12: percentage | E12: 95 | F12: >= | G12: % | H12: Semanal | I12: execution
A13: SC-009 | B13: patient_retention_monthly | C13: Retención de Pacientes | D13: percentage | E13: 90 | F13: >= | G13: % | H13: Mensual | I13: execution
A14: SC-010 | B14: sae_reported_on_time | C14: % SAEs Reportados en Plazo | D14: percentage | E14: 100 | F14: = | G14: % | H14: Por evento | I14: safety
A15: SC-011 | B15: major_deviations_weekly | C15: Desviaciones Mayores (semana) | D15: count | E15: 2 | F15: <= | G15: qty | H15: Semanal | I15: safety
A16: SC-012 | B16: protocol_deviation_rate | C16: Tasa Desviaciones Protocolo | D16: percentage | E16: 3 | F16: <= | G16: % | H16: Mensual | I16: safety
... A28: SC-028 | B28: ec_approval_cycle_days | C28: Tiempo Ciclo Aprobación EC | D28: number | E28: 45 | F28: <= | G28: días | H28: Por estudio | I28: startup
A29: SC-029 | B29: studies_in_startup | C29: Estudios en Start-Up Activos | D29: count | E29: N/A | F29: info | G29: qty | H29: Semanal | I29: startup
A30: SC-030 | B30: pending_amendments | C30: Enmiendas Pendientes Aprobación | D30: count | E30: N/A | F30: info | G30: qty | H30: Semanal | I30: startup
A31: SC-031 | B31: sponsor_performance_score | C31: Score Evaluación Performance | D31: decimal | E31: 4 | F31: >= | G31: /5.0 | H31: Trimestral | I31: sponsor
A32: SC-032 | B32: cra_response_48h | C32: % Consultas CRA/Sponsor ≤48h | D32: percentage | E32: 90 | F32: >= | G32: % | H32: Semanal | I32: sponsor
A33: SC-033 | B33: sponsor_nps | C33: NPS de Sponsors | D33: decimal | E33: 8 | F33: >= | G33: /10 | H33: Trimestral | I33: sponsor
A34: SC-034 | B34: annual_turnover | C34: Turnover Anual Equipo | D34: percentage | E34: 18 | F34: <= | G34: % | H34: Anual | I34: team
A35: SC-035 | B35: satisfactory_performance_pct | C35: % Equipo Evaluación Satisfactoria | D35: percentage | E35: 80 | F35: >= | G35: % | H35: Semestral | I35: team
A36: SC-036 | B36: gcp_current_pct | C36: % Equipo GCP Vigente | D36: percentage | E36: 100 | F36: = | G36: % | H36: Mensual | I36: team
A37: SC-037 | B37: span_of_control | C37: Span of Control | D37: count | E37: 8 | F37: <= | G37: reportes | H37: Mensual | I37: team
A38: SC-038 | B38: training_completion_pct | C38: Training Completado vs Plan | D38: percentage | E38: 90 | F38: >= | G38: % | H38: Mensual | I38: team
A39: SC-039 | B39: workload_score | C39: Workload Score Equipo | D39: decimal | E39: 2.5-3.5 | F39: range | G39: score | H39: Semanal | I39: team
A40: SC-040 | B40: studies_per_coordinator | C40: Estudios Activos por Coordinador | D40: decimal | E40: 3-5 | F40: range | G40: qty | H40: Mensual | I40: efficiency
A41: SC-041 | B41: patients_per_coordinator | C41: Pacientes Activos por Coordinador | D41: decimal | E41: 15-25 | F41: range | G41: qty | H41: Semanal | I41: efficiency
A42: SC-042 | B42: contingency_resolution_hours | C42: Tiempo Resolución Contingencias | D42: number | E42: 4 | F42: <= | G42: horas | H42: Por evento | I42: efficiency
A43: SC-043 | B43: mv_siv_participation | C43: % Participación en MV/SIV | D43: percentage | E43: 100 | F43: = | G43: % | H43: Por visita | I43: efficiency

Sheet Guía Rápida
A1: 📖 GUÍA RÁPIDA - DASHBOARD SC LEAD
A3: 📝 FLUJO DE TRABAJO:
A5: 1. Registro Semanal | B5: Complete métricas de reclutamiento, visitas, seguridad y eficiencia (10-15 min)
A6: 2. Tracking Action Items | B6: Actualice estado de Action Items de monitoring visits
A7: 3. Contacto Pacientes | B7: Registre pacientes derivados y fecha de contacto
A8: 4. Start-up Tracker | B8: Mantenga actualizado el estado de estudios en activación
A9: 5. Consultas CRA-Sponsor | B9: Registre consultas recibidas y tiempos de respuesta
A10: 6. Gestión Equipo | B10: Actualice roster, trainings y movimientos de personal (mensual)
A11: 7. Evaluación Sponsor | B11: Complete evaluaciones trimestrales de sponsors
A12: 8. Contingencias | B12: Registre contingencias operativas y resolución
A13: 9. Audit Readiness | B13: Complete checklist mensual de preparación para auditorías
A14: 10. Scorecard SC Lead | B14: Revise el consolidado automático de todos los KPIs
A16: 🎯 CONEXIONES ENTRE HOJAS:
A18: Registro Semanal → | B18: Alimenta 16 KPIs (reclutamiento, visitas, seguridad, eficiencia)
A19: Tracking Action Items → | B19: Alimenta 5 KPIs de monitoring (SC-019 a SC-023)
A20: Contacto Pacientes → | B20: Alimenta KPI SC-003 (tiempo derivación→contacto)
A21: Start-up Tracker → | B21: Alimenta 6 KPIs de start-up (SC-025 a SC-030)
A22: Consultas CRA-Sponsor → | B22: Alimenta KPI SC-032 (responsiveness)
A23: Gestión Equipo → | B23: Alimenta 6 KPIs de equipo (SC-034 a SC-039)
A24: Evaluación Sponsor → | B24: Alimenta KPIs SC-031 y SC-033
A25: Contingencias → | B25: Alimenta KPI SC-042 (tiempo resolución)
A26: Audit Readiness → | B26: Alimenta KPI SC-024 (audit readiness score)
A28: ⚠️ IMPORTANTE:
A30: • Solo complete celdas en AZUL | B30: Las celdas VERDES son cálculos automáticos
A31: • Use validaciones de dropdown | B31: Aseguran consistencia de datos
A32: • Fechas en formato DD/MM/AAAA | B32: Para cálculos correctos de días
A33: • Estados válidos: | B33: Abierto | En Progreso | Cerrado
A35: 📊 TOTAL KPIs: | B35: 39 (excluyendo Data Quality que va a CTMS/QA)
A37: 📂 CATEGORÍAS:
A38: • Reclutamiento: | B38: 5 KPIs
A39: • Ejecución de Visitas: | B39: 4 KPIs
A40: • Seguridad y Compliance: | B40: 5 KPIs
A41: • Monitoring Action Items: | B41: 6 KPIs
A42: • Start-up y Regulatorio: | B42: 6 KPIs
A43: • Satisfacción Sponsors: | B43: 3 KPIs
A44: • Gestión de Equipo: | B44: 6 KPIs
A45: • Eficiencia Operativa: | B45: 4 KPIs
